<?xml version="1.0" encoding="UTF-8"?>
<testng-results skipped="0" failed="1" ignored="1" total="2" passed="0">
  <reporter-output>
  </reporter-output>
  <suite name="Failed suite [functional]" duration-ms="127" started-at="2021-08-20T12:31:08 IST" finished-at="2021-08-20T12:31:08 IST">
    <groups>
    </groups>
    <test name="Test1(failed)" duration-ms="127" started-at="2021-08-20T12:31:08 IST" finished-at="2021-08-20T12:31:08 IST">
      <class name="testNG.TestCase3">
        <test-method status="FAIL" signature="m5()[pri:0, instance:testNG.TestCase3@7364985f]" name="m5" duration-ms="27" started-at="2021-08-20T12:31:08 IST" finished-at="2021-08-20T12:31:08 IST">
          <exception class="java.lang.AssertionError">
            <message>
              <![CDATA[expected [true] but found [false]]]>
            </message>
            <full-stacktrace>
              <![CDATA[java.lang.AssertionError: expected [true] but found [false]
at org.testng.Assert.fail(Assert.java:99)
at org.testng.Assert.failNotEquals(Assert.java:1037)
at org.testng.Assert.assertTrue(Assert.java:45)
at org.testng.Assert.assertTrue(Assert.java:55)
at testNG.TestCase3.m5(TestCase3.java:10)
at sun.reflect.NativeMethodAccessorImpl.invoke0(Native Method)
at sun.reflect.NativeMethodAccessorImpl.invoke(NativeMethodAccessorImpl.java:62)
at sun.reflect.DelegatingMethodAccessorImpl.invoke(DelegatingMethodAccessorImpl.java:43)
at java.lang.reflect.Method.invoke(Method.java:483)
at org.testng.internal.MethodInvocationHelper.invokeMethod(MethodInvocationHelper.java:133)
at org.testng.internal.TestInvoker.invokeMethod(TestInvoker.java:598)
at org.testng.internal.TestInvoker.invokeTestMethod(TestInvoker.java:173)
at org.testng.internal.MethodRunner.runInSequence(MethodRunner.java:46)
at org.testng.internal.TestInvoker$MethodInvocationAgent.invoke(TestInvoker.java:824)
at org.testng.internal.TestInvoker.invokeTestMethods(TestInvoker.java:146)
at org.testng.internal.TestMethodWorker.invokeTestMethods(TestMethodWorker.java:146)
at org.testng.internal.TestMethodWorker.run(TestMethodWorker.java:128)
at org.testng.TestRunner$$Lambda$93/2084663827.accept(Unknown Source)
at java.util.ArrayList.forEach(ArrayList.java:1234)
at org.testng.TestRunner.privateRun(TestRunner.java:794)
at org.testng.TestRunner.run(TestRunner.java:596)
at org.testng.SuiteRunner.runTest(SuiteRunner.java:377)
at org.testng.SuiteRunner.runSequentially(SuiteRunner.java:371)
at org.testng.SuiteRunner.privateRun(SuiteRunner.java:332)
at org.testng.SuiteRunner.run(SuiteRunner.java:276)
at org.testng.SuiteRunnerWorker.runSuite(SuiteRunnerWorker.java:53)
at org.testng.SuiteRunnerWorker.run(SuiteRunnerWorker.java:96)
at org.testng.TestNG.runSuitesSequentially(TestNG.java:1212)
at org.testng.TestNG.runSuitesLocally(TestNG.java:1134)
at org.testng.TestNG.runSuites(TestNG.java:1063)
at org.testng.TestNG.run(TestNG.java:1031)
at org.testng.remote.AbstractRemoteTestNG.run(AbstractRemoteTestNG.java:115)
at org.testng.remote.RemoteTestNG.initAndRun(RemoteTestNG.java:251)
at org.testng.remote.RemoteTestNG.main(RemoteTestNG.java:77)
]]>
            </full-stacktrace>
          </exception> <!-- java.lang.AssertionError -->
          <reporter-output>
          </reporter-output>
        </test-method> <!-- m5 -->
      </class> <!-- testNG.TestCase3 -->
    </test> <!-- Test1(failed) -->
  </suite> <!-- Failed suite [functional] -->
</testng-results>
